Workbook

Sheet Dropdown
A1: Supplier | B1: Alias | C1: Period | D1: Type
A2: CHAKRAPANI VYAPAR PRIVATE LIMITED | B2: CVPL | C2: 45748 | D2: Discounts
A3: PARAGON RESIN LLP | B3: Paragon | C3: 45778 | D3: Outright with Discounts
A4: KAMAKYA CHEMPLAST PRIVATE LIMITED | B4: Kamakya | C4: 45809 | D4: Outright
A5: INTIME VINCOM PRIVATE LIMITED | B5: Intime | C5: 45839
A6: TREENITY PLY DECOR | B6: Treenity | C6: 45870
A7: PURAV POLYMERS PRIVATE LIMITED | B7: Purav | C7: 45901
A8: PRESTINE VENTURES PRIVATE LIMITED | B8: Prestine | C8: 45931
A9: VALUE PACKAGING INDUSTRIES PRIVATE LIMITED | B9: Value | C9: 45962
A10: SRI VENKATESHWARA POLYMERS | B10: SVP | C10: 45992
A11: ALLIED PLASTICS | B11: Allied | C11: 46023
C12: 46054
C13: 46082

Sheet Items Master
A1: Item Name | B1: Type | C1: HSN Code | D1: Product Cat | E1: Company | F1: Type
A2: HD M BLOW 003DB52 IOCL | B2: Domestic | C2: 39012000 | D2: HDPE | E2: IOCL | F2: Domestic
A3: PPCP 7033 E3 EXXON | B3: Import | C3: 39023000 | D3: PP ICP | E3: EXXON | F3: Import
A4: LD LAMINATION 1070LA17 RIL | B4: Domestic | C4: 39011020 | D4: LDPE | E4: RIL | F4: Domestic
A5: HD PIPE PE-100 002DP48 IOCL | B5: Domestic | C5: 39012000 | D5: HDPE | E5: IOCL | F5: Domestic
A6: LL FILM SLIP 010F18S IOCL | B6: Domestic | C6: 39012000 | D6: LLDPE | E6: IOCL | F6: Domestic
A7: HD PIPE PE-80 004DP44 IOCL | B7: Domestic | C7: 39012000 | D7: HDPE | E7: IOCL | F7: Domestic
A8: HD PIPE PE-63 010DP45 IOCL | B8: Domestic | C8: 39012000 | D8: HDPE | E8: IOCL | F8: Domestic
A9: LD FILM NON SLIP 450E DOW | B9: Import | C9: 39019090 | D9: LDPE | E9: DOW | F9: Import
A10: LD HEAVY DUTY FB3003 LOTRENE | B10: Import | C10: 39011090 | D10: LDPE | E10: LOTRENE | F10: Import
A11: HDPE 1007 | B11: Import | C11: 39012000 | D11: HDPE | E11: NA | F11: Others
A12: HDPE 3007 | B12: Import | C12: 39012000 | D12: HDPE | E12: NA | F12: Others
... A303: ABS MODIFIED TRANSPARENT 929-555 TORAY | B303: Import | C303: 39069090 | D303: ABS | E303: TORAY | F303: Import
A304: XYRON 540Z A1A3301 (BLACK) | B304: Import | C304: 39072090 | E304: XYRON | F304: Import
A305: XYRON PV40Z A1A3201 (BLACK) | B305: Import | C305: 39072990 | E305: XYRON | F305: Import
A306: LEONA FR370 W33N2 (BLACK) | B306: Import | C306: 39081049 | E306: LEONA | F306: Import

Sheet As per Zoho
B1: =SUBTOTAL(9, B3:B1048576) -> 1327852 | C1: =SUBTOTAL(9, C3:C1048576) -> 1443689 | D1: =SUBTOTAL(9, D3:D1048576) -> 1234725 | E1: =SUBTOTAL(9, E3:E1048576) -> 972325 | F1: =SUBTOTAL(9, F3:F1048576) -> 953000 | G1: =SUBTOTAL(9, G3:G1048576) -> 1220800 | H1: =SUBTOTAL(9, H3:H1048576) -> 978875
A2: Vendor Name | B2: 45748 | C2: 45778 | D2: 45809 | E2: 45839 | F2: 45870 | G2: 45901 | H2: 45931 | I2: 45962 | J2: 45992 | K2: 46023 | L2: 46054 | M2: 46082
A3: PARAGON RESIN LLP | B3: 87525 | C3: 94325 | D3: 60625 | E3: 31400 | F3: 25175 | G3: 55425 | H3: 28775
A4: HARISHREE POLYMERS PRIVATE LIMITED | B4: 78000 | C4: 36000 | D4: 2100 | E4: 21000 | F4: 10000 | G4: 12000 | H4: 0
A5: KAMAKYA CHEMPLAST PRIVATE LIMITED | B5: 70100 | C5: 25000 | D5: 0 | E5: 0 | F5: 105000 | G5: 25000 | H5: 25000
A6: RAGHUSHARAN OVERSEAS PRIVATE LIMITED | B6: 114250 | C6: 0 | D6: 0 | E6: 0 | F6: 0 | G6: 0 | H6: 0
A7: SHUBHAM INTERNATIONAL PRIVATE LIMITED | B7: 20500 | C7: 0 | D7: 500 | E7: 0 | F7: 7000 | G7: 10500 | H7: 0
A8: CHAKRAPANI VYAPAR PRIVATE LIMITED | B8: 25600 | C8: 166550 | D8: 108750 | E8: 158250 | F8: 150000 | G8: 173825 | H8: 220750
A9: NAGASHREE INDUSTRIES | B9: 0 | C9: 0 | D9: 0 | E9: 0 | F9: 0 | G9: 0 | H9: 0
A10: BULK LIQUID SOLUTIONS PVT LTD | B10: 54750 | C10: 10000 | D10: 17000 | E10: 47200 | F10: 0 | G10: 10000 | H10: 0
A11: TRIMURTI POLYCHEM PRIVATE LIMITED | B11: 24750 | C11: 0 | D11: 0 | E11: 0 | F11: 0 | G11: 0 | H11: 0
A12: AMBIKA PETROCHEM PRIVATE LIMITED | B12: 37000 | C12: 0 | D12: 12000 | E12: 0 | F12: 0 | G12: 0 | H12: 0
A13: SQUAREFLEX PACKAGING PRIVATE LIMITED | B13: 10000 | C13: 20000 | D13: 0 | E13: 0 | F13: 0 | G13: 0 | H13: 0
A14: D R POLYMERS PRIVATE LIMITED | B14: 40000 | C14: 14000 | D14: 0 | E14: 0 | F14: 0 | G14: 0 | H14: 17000
... A78: AXIA PLASTICS PRIVATE LIMITED | B78: 0 | C78: 0 | D78: 0 | E78: 0 | F78: 0 | G78: 24750 | H78: 30000

Sheet Master Check
A1: Period | B1: 45931
A3: Supplier | B3: As per Books | C3: As per Working | D3: Diff
A4: PARAGON RESIN LLP | B4: =VLOOKUP(A4,'As per Zoho'!$A:$M,MATCH('Master Check'!$B$1,'As per Zoho'!$A$2:$M$2),) -> 28775 | C4: =SUMIFS('<< Working >>'!$J:$J, '<< Working >>'!$G:$G, 'Master Check'!$B$1, '<< Working >>'!$D:$D, 'Master Check'!$A4) -> 28775 | D4: =B4-C4 -> 0
A5: HARISHREE POLYMERS PRIVATE LIMITED | B5: =VLOOKUP(A5,'As per Zoho'!$A:$M,MATCH('Master Check'!$B$1,'As per Zoho'!$A$2:$M$2),) -> 0 | C5: =SUMIFS('<< Working >>'!$J:$J, '<< Working >>'!$G:$G, 'Master Check'!$B$1, '<< Working >>'!$D:$D, 'Master Check'!$A5) -> 0 | D5: =B5-C5 -> 0
A6: KAMAKYA CHEMPLAST PRIVATE LIMITED | B6: =VLOOKUP(A6,'As per Zoho'!$A:$M,MATCH('Master Check'!$B$1,'As per Zoho'!$A$2:$M$2),) -> 25000 | C6: =SUMIFS('<< Working >>'!$J:$J, '<< Working >>'!$G:$G, 'Master Check'!$B$1, '<< Working >>'!$D:$D, 'Master Check'!$A6) -> 25000 | D6: =B6-C6 -> 0
A7: RAGHUSHARAN OVERSEAS PRIVATE LIMITED | B7: =VLOOKUP(A7,'As per Zoho'!$A:$M,MATCH('Master Check'!$B$1,'As per Zoho'!$A$2:$M$2),) -> 0 | C7: =SUMIFS('<< Working >>'!$J:$J, '<< Working >>'!$G:$G, 'Master Check'!$B$1, '<< Working >>'!$D:$D, 'Master Check'!$A7) -> 0 | D7: =B7-C7 -> 0
A8: SHUBHAM INTERNATIONAL PRIVATE LIMITED | B8: =VLOOKUP(A8,'As per Zoho'!$A:$M,MATCH('Master Check'!$B$1,'As per Zoho'!$A$2:$M$2),) -> 0 | C8: =SUMIFS('<< Working >>'!$J:$J, '<< Working >>'!$G:$G, 'Master Check'!$B$1, '<< Working >>'!$D:$D, 'Master Check'!$A8) -> 0 | D8: =B8-C8 -> 0
A9: CHAKRAPANI VYAPAR PRIVATE LIMITED | B9: =VLOOKUP(A9,'As per Zoho'!$A:$M,MATCH('Master Check'!$B$1,'As per Zoho'!$A$2:$M$2),) -> 220750 | C9: =SUMIFS('<< Working >>'!$J:$J, '<< Working >>'!$G:$G, 'Master Check'!$B$1, '<< Working >>'!$D:$D, 'Master Check'!$A9) -> 220750 | D9: =B9-C9 -> 0
A10: NAGASHREE INDUSTRIES | B10: =VLOOKUP(A10,'As per Zoho'!$A:$M,MATCH('Master Check'!$B$1,'As per Zoho'!$A$2:$M$2),) -> 0 | C10: =SUMIFS('<< Working >>'!$J:$J, '<< Working >>'!$G:$G, 'Master Check'!$B$1, '<< Working >>'!$D:$D, 'Master Check'!$A10) -> 0 | D10: =B10-C10 -> 0
A11: BULK LIQUID SOLUTIONS PVT LTD | B11: =VLOOKUP(A11,'As per Zoho'!$A:$M,MATCH('Master Check'!$B$1,'As per Zoho'!$A$2:$M$2),) -> 0 | C11: =SUMIFS('<< Working >>'!$J:$J, '<< Working >>'!$G:$G, 'Master Check'!$B$1, '<< Working >>'!$D:$D, 'Master Check'!$A11) -> 0 | D11: =B11-C11 -> 0
A12: TRIMURTI POLYCHEM PRIVATE LIMITED | B12: =VLOOKUP(A12,'As per Zoho'!$A:$M,MATCH('Master Check'!$B$1,'As per Zoho'!$A$2:$M$2),) -> 0 | C12: =SUMIFS('<< Working >>'!$J:$J, '<< Working >>'!$G:$G, 'Master Check'!$B$1, '<< Working >>'!$D:$D, 'Master Check'!$A12) -> 0 | D12: =B12-C12 -> 0
A13: AMBIKA PETROCHEM PRIVATE LIMITED | B13: =VLOOKUP(A13,'As per Zoho'!$A:$M,MATCH('Master Check'!$B$1,'As per Zoho'!$A$2:$M$2),) -> 0 | C13: =SUMIFS('<< Working >>'!$J:$J, '<< Working >>'!$G:$G, 'Master Check'!$B$1, '<< Working >>'!$D:$D, 'Master Check'!$A13) -> 0 | D13: =B13-C13 -> 0
A14: SQUAREFLEX PACKAGING PRIVATE LIMITED | B14: =VLOOKUP(A14,'As per Zoho'!$A:$M,MATCH('Master Check'!$B$1,'As per Zoho'!$A$2:$M$2),) -> 0 | C14: =SUMIFS('<< Working >>'!$J:$J, '<< Working >>'!$G:$G, 'Master Check'!$B$1, '<< Working >>'!$D:$D, 'Master Check'!$A14) -> 0 | D14: =B14-C14 -> 0
A15: D R POLYMERS PRIVATE LIMITED | B15: =VLOOKUP(A15,'As per Zoho'!$A:$M,MATCH('Master Check'!$B$1,'As per Zoho'!$A$2:$M$2),) -> 17000 | C15: =SUMIFS('<< Working >>'!$J:$J, '<< Working >>'!$G:$G, 'Master Check'!$B$1, '<< Working >>'!$D:$D, 'Master Check'!$A15) -> 17000 | D15: =B15-C15 -> 0
... A73: KULODAY TECHNOPACK PVT.LTD | B73: =VLOOKUP(A73,'As per Zoho'!$A:$M,MATCH('Master Check'!$B$1,'As per Zoho'!$A$2:$M$2),) -> 0 | C73: =SUMIFS('<< Working >>'!$J:$J, '<< Working >>'!$G:$G, 'Master Check'!$B$1, '<< Working >>'!$D:$D, 'Master Check'!$A73) -> 0 | D73: =B73-C73 -> 0

Sheet << Working >>
J1: =SUBTOTAL(9, J3:J1048576) -> 8728791 | W1: If Type = Outright & Outright W/D | X1: If Type = Discounts (always consider after CD) | AB1: Reconciliation
A2: Sr. No. | B2: Category | C2: PSPL Branch | D2: Supplier | E2: Alias | F2: Purchase Date | G2: Bill Month | H2: Bill No. | I2: Buy Rate | J2: QTY | K2: Grade | L2: Company | M2: Product Cat | N2: Type | O2: Buying Terms (If Outright with Disc) | Q2: Date for CN | R2: CN Month | S2: EBI | T2: PP | U2: Source | W2: Rate, As per Confirmation | X2: Rate, As per Price List | Y2: Price Type | Z2: Location | AB2: MOU | AC2: QD | AD2: EBI | AE2: GSI | AF2: Scheme | AG2: Extra | AH2: Loading | AI2: TPT | AJ2: Insurance | AK2: Round Off | AL2: Commission | AM2: GST CN | AN2: Total | AP2: Diff | AQ2: Status | AR2: Remarks, if any diff
A3: 1 | B3: Purchase | C3: Bangalore WH | D3: PARAGON RESIN LLP | E3: =IFERROR(VLOOKUP(D3,Dropdown!A:B,2,0),D3) -> Paragon | F3: 45748 | G3: =TEXT(F3, "MMM-YY") -> Apr-25 | H3: 10 | I3: 120.5 | J3: 2500 | K3: LD SLIP J24FS040 RIL | L3: =VLOOKUP(K3, 'Items Master'!A:E,5,0) -> RIL | M3: =VLOOKUP(K3, 'Items Master'!A:D,4,0) -> LDPE | N3: Outright | Q3: 45748 | R3: =TEXT(Q3, "MMM-YY") -> Apr-25 | W3: 120.5 | AN3: =SUM(AB3:AM3) -> 0 | AP3: =I3-W3-X3-AN3 -> 0 | AQ3: Verified & Closed
A4: =A3+1 -> 2 | B4: Purchase | C4: Bangalore WH | D4: HARISHREE POLYMERS PRIVATE LIMITED | E4: =IFERROR(VLOOKUP(D4,Dropdown!A:B,2,0),D4) -> HARISHREE POLYMERS PRIVATE LIMITED | F4: 45749 | G4: =TEXT(F4, "MMM-YY") -> Apr-25 | H4: HS/2526/00026 | I4: 91 | J4: 7000 | K4: HDPE HM F52H04 OPAL | L4: =VLOOKUP(K4, 'Items Master'!A:E,5,0) -> OPAL | M4: =VLOOKUP(K4, 'Items Master'!A:D,4,0) -> HDPE | N4: Outright | Q4: 45749 | R4: =TEXT(Q4, "MMM-YY") -> Apr-25 | W4: 91 | AN4: =SUM(AB4:AM4) -> 0 | AP4: =I4-W4-X4-AN4 -> 0 | AQ4: Verified & Closed
A5: =A4+1 -> 3 | B5: Purchase | C5: Bangalore WH | D5: HARISHREE POLYMERS PRIVATE LIMITED | E5: =IFERROR(VLOOKUP(D5,Dropdown!A:B,2,0),D5) -> HARISHREE POLYMERS PRIVATE LIMITED | F5: 45749 | G5: =TEXT(F5, "MMM-YY") -> Apr-25 | H5: HS/2526/00026 | I5: 95.5 | J5: 5000 | K5: LLDPE NONSLIP F2003A OPAL | L5: =VLOOKUP(K5, 'Items Master'!A:E,5,0) -> OPAL | M5: =VLOOKUP(K5, 'Items Master'!A:D,4,0) -> LLDPE | N5: Outright | Q5: 45749 | R5: =TEXT(Q5, "MMM-YY") -> Apr-25 | W5: 95.5 | AN5: =SUM(AB5:AM5) -> 0 | AP5: =I5-W5-X5-AN5 -> 0 | AQ5: Verified & Closed
A6: =A5+1 -> 4 | B6: Purchase | C6: Bangalore WH | D6: HARISHREE POLYMERS PRIVATE LIMITED | E6: =IFERROR(VLOOKUP(D6,Dropdown!A:B,2,0),D6) -> HARISHREE POLYMERS PRIVATE LIMITED | F6: 45749 | G6: =TEXT(F6, "MMM-YY") -> Apr-25 | H6: HS/2526/00027 | I6: 95.5 | J6: 10000 | K6: LLDPE NON-SLIP F2002A OPAL | L6: =VLOOKUP(K6, 'Items Master'!A:E,5,0) -> OPAL | M6: =VLOOKUP(K6, 'Items Master'!A:D,4,0) -> LLDPE | N6: Outright | Q6: 45749 | R6: =TEXT(Q6, "MMM-YY") -> Apr-25 | W6: 95.5 | AN6: =SUM(AB6:AM6) -> 0 | AP6: =I6-W6-X6-AN6 -> 0 | AQ6: Verified & Closed
A7: =A6+1 -> 5 | B7: Purchase | C7: Bangalore WH | D7: KAMAKYA CHEMPLAST PRIVATE LIMITED | E7: =IFERROR(VLOOKUP(D7,Dropdown!A:B,2,0),D7) -> Kamakya | F7: 45749 | G7: =TEXT(F7, "MMM-YY") -> Apr-25 | H7: 1 | I7: 98.9 | J7: 10100 | K7: PP RAFFIA HR003 MRPL | L7: =VLOOKUP(K7, 'Items Master'!A:E,5,0) -> MRPL | M7: =VLOOKUP(K7, 'Items Master'!A:D,4,0) -> PP | N7: Discounts | Q7: 45747 | R7: =TEXT(Q7, "MMM-YY") -> Mar-25 | X7: 98.9 | Y7: Ex-Works | Z7: Bangalore | AN7: =SUM(AB7:AM7) -> 0 | AP7: =I7-W7-X7-AN7 -> 0 | AQ7: Verified & Closed
A8: =A7+1 -> 6 | B8: Purchase | C8: Bangalore WH | D8: RAGHUSHARAN OVERSEAS PRIVATE LIMITED | E8: =IFERROR(VLOOKUP(D8,Dropdown!A:B,2,0),D8) -> RAGHUSHARAN OVERSEAS PRIVATE LIMITED | F8: 45749 | G8: =TEXT(F8, "MMM-YY") -> Apr-25 | H8: RO/CH/25-26/0004 | I8: 67.8 | J8: 30000 | K8: PVC SUSPENSION RESIN HS1000R | L8: =VLOOKUP(K8, 'Items Master'!A:E,5,0) -> HANWHA | M8: =VLOOKUP(K8, 'Items Master'!A:D,4,0) -> PVC | N8: Outright | Q8: 45749 | R8: =TEXT(Q8, "MMM-YY") -> Apr-25 | W8: 67.8 | AN8: =SUM(AB8:AM8) -> 0 | AP8: =I8-W8-X8-AN8 -> 0 | AQ8: Verified & Closed
A9: =A8+1 -> 7 | B9: Purchase | C9: Chennai Office | D9: SHUBHAM INTERNATIONAL PRIVATE LIMITED | E9: =IFERROR(VLOOKUP(D9,Dropdown!A:B,2,0),D9) -> SHUBHAM INTERNATIONAL PRIVATE LIMITED | F9: 45750 | G9: =TEXT(F9, "MMM-YY") -> Apr-25 | H9: 11 | I9: 98.5 | J9: 3000 | K9: PP TQ FILM HF010 MRPL | L9: =VLOOKUP(K9, 'Items Master'!A:E,5,0) -> MRPL | M9: =VLOOKUP(K9, 'Items Master'!A:D,4,0) -> PP | N9: Outright | Q9: 45750 | R9: =TEXT(Q9, "MMM-YY") -> Apr-25 | W9: 98.5 | AN9: =SUM(AB9:AM9) -> 0 | AP9: =I9-W9-X9-AN9 -> 0 | AQ9: Verified & Closed
A10: =A9+1 -> 8 | B10: Purchase | C10: Bangalore WH | D10: CHAKRAPANI VYAPAR PRIVATE LIMITED | E10: =IFERROR(VLOOKUP(D10,Dropdown!A:B,2,0),D10) -> CVPL | F10: 45751 | G10: =TEXT(F10, "MMM-YY") -> Apr-25 | H10: CV2526BGP000053 | I10: 97.75 | J10: 1400 | K10: LLDPE SLIP F20S009 GAIL | L10: =VLOOKUP(K10, 'Items Master'!A:E,5,0) -> GAIL | M10: =VLOOKUP(K10, 'Items Master'!A:D,4,0) -> LLDPE | N10: Outright | Q10: 45751 | R10: =TEXT(Q10, "MMM-YY") -> Apr-25 | W10: 97.75 | AN10: =SUM(AB10:AM10) -> 0 | AP10: =I10-W10-X10-AN10 -> 0 | AQ10: Verified & Closed
A11: =A10+1 -> 9 | B11: Purchase | C11: Bangalore WH | D11: CHAKRAPANI VYAPAR PRIVATE LIMITED | E11: =IFERROR(VLOOKUP(D11,Dropdown!A:B,2,0),D11) -> CVPL | F11: 45751 | G11: =TEXT(F11, "MMM-YY") -> Apr-25 | H11: CV2526BGP000053 | I11: 120.75 | J11: 100 | K11: LD SLIP J24FS040 RIL | L11: =VLOOKUP(K11, 'Items Master'!A:E,5,0) -> RIL | M11: =VLOOKUP(K11, 'Items Master'!A:D,4,0) -> LDPE | N11: Outright | Q11: 45751 | R11: =TEXT(Q11, "MMM-YY") -> Apr-25 | W11: 120.75 | AN11: =SUM(AB11:AM11) -> 0 | AP11: =I11-W11-X11-AN11 -> 0 | AQ11: Verified & Closed
A12: =A11+1 -> 10 | B12: Purchase | C12: Bangalore WH | D12: CHAKRAPANI VYAPAR PRIVATE LIMITED | E12: =IFERROR(VLOOKUP(D12,Dropdown!A:B,2,0),D12) -> CVPL | F12: 45751 | G12: =TEXT(F12, "MMM-YY") -> Apr-25 | H12: CV2526YPR000311 | I12: 97 | J12: 3000 | K12: LLDPE F18S010UA GAIL | L12: =VLOOKUP(K12, 'Items Master'!A:E,5,0) -> GAIL | M12: =VLOOKUP(K12, 'Items Master'!A:D,4,0) -> LLDPE | N12: Outright | Q12: 45751 | R12: =TEXT(Q12, "MMM-YY") -> Apr-25 | W12: 97 | AN12: =SUM(AB12:AM12) -> 0 | AP12: =I12-W12-X12-AN12 -> 0 | AQ12: Verified & Closed
A13: =A12+1 -> 11 | B13: Purchase | C13: Bangalore WH | D13: HARISHREE POLYMERS PRIVATE LIMITED | E13: =IFERROR(VLOOKUP(D13,Dropdown!A:B,2,0),D13) -> HARISHREE POLYMERS PRIVATE LIMITED | F13: 45751 | G13: =TEXT(F13, "MMM-YY") -> Apr-25 | H13: HS/2526/00089 | I13: 91 | J13: 12000 | K13: HDPE HM F52H04 OPAL | L13: =VLOOKUP(K13, 'Items Master'!A:E,5,0) -> OPAL | M13: =VLOOKUP(K13, 'Items Master'!A:D,4,0) -> HDPE | N13: Outright | Q13: 45751 | R13: =TEXT(Q13, "MMM-YY") -> Apr-25 | W13: 91 | AN13: =SUM(AB13:AM13) -> 0 | AP13: =I13-W13-X13-AN13 -> 0 | AQ13: Verified & Closed
A14: =A13+1 -> 12 | B14: Purchase | C14: Bangalore WH | D14: HARISHREE POLYMERS PRIVATE LIMITED | E14: =IFERROR(VLOOKUP(D14,Dropdown!A:B,2,0),D14) -> HARISHREE POLYMERS PRIVATE LIMITED | F14: 45751 | G14: =TEXT(F14, "MMM-YY") -> Apr-25 | H14: HS/2526/00088 | I14: 95.75 | J14: 12000 | K14: LLDPE SLIP F2001S OPAL | L14: =VLOOKUP(K14, 'Items Master'!A:E,5,0) -> OPAL | M14: =VLOOKUP(K14, 'Items Master'!A:D,4,0) -> LLDPE | N14: Outright | Q14: 45751 | R14: =TEXT(Q14, "MMM-YY") -> Apr-25 | W14: 95.75 | AN14: =SUM(AB14:AM14) -> 0 | AP14: =I14-W14-X14-AN14 -> 0 | AQ14: Verified & Closed
A15: =A14+1 -> 13 | B15: Purchase | C15: Bangalore WH | D15: SHUBHAM INTERNATIONAL PRIVATE LIMITED | E15: =IFERROR(VLOOKUP(D15,Dropdown!A:B,2,0),D15) -> SHUBHAM INTERNATIONAL PRIVATE LIMITED | F15: 45751 | G15: =TEXT(F15, "MMM-YY") -> Apr-25 | H15: 22 | I15: 120.75 | J15: 3500 | K15: LD SLIP J24FS040 RIL | L15: =VLOOKUP(K15, 'Items Master'!A:E,5,0) -> RIL | M15: =VLOOKUP(K15, 'Items Master'!A:D,4,0) -> LDPE | N15: Outright | Q15: 45751 | R15: =TEXT(Q15, "MMM-YY") -> Apr-25 | W15: 120.75 | AN15: =SUM(AB15:AM15) -> 0 | AP15: =I15-W15-X15-AN15 -> 0 | AQ15: Verified & Closed
A16: =A15+1 -> 14 | B16: Purchase | C16: Bangalore WH | D16: NAGASHREE INDUSTRIES | E16: =IFERROR(VLOOKUP(D16,Dropdown!A:B,2,0),D16) -> NAGASHREE INDUSTRIES | F16: 45751 | G16: =TEXT(F16, "MMM-YY") -> Apr-25 | H16: NI/005/25-26 | I16: 107 | J16: 350 | K16: PP RANDOM RE420MO BOROUGE | L16: =VLOOKUP(K16, 'Items Master'!A:E,5,0) -> BOROUGE | M16: =VLOOKUP(K16, 'Items Master'!A:D,4,0) -> PP RCP | N16: Outright | Q16: 45751 | R16: =TEXT(Q16, "MMM-YY") -> Apr-25 | W16: 107 | AN16: =SUM(AB16:AM16) -> 0 | AP16: =I16-W16-X16-AN16 -> 0 | AQ16: Verified & Closed
A17: =A16+1 -> 15 | B17: Purchase | C17: Bangalore WH | D17: SHUBHAM INTERNATIONAL PRIVATE LIMITED | E17: =IFERROR(VLOOKUP(D17,Dropdown!A:B,2,0),D17) -> SHUBHAM INTERNATIONAL PRIVATE LIMITED | F17: 45752 | G17: =TEXT(F17, "MMM-YY") -> Apr-25 | H17: 26 | I17: 120.75 | J17: 1500 | K17: LD SLIP J24FS040 RIL | L17: =VLOOKUP(K17, 'Items Master'!A:E,5,0) -> RIL | M17: =VLOOKUP(K17, 'Items Master'!A:D,4,0) -> LDPE | N17: Outright | Q17: 45752 | R17: =TEXT(Q17, "MMM-YY") -> Apr-25 | W17: 120.75 | AN17: =SUM(AB17:AM17) -> 0 | AP17: =I17-W17-X17-AN17 -> 0 | AQ17: Verified & Closed
A18: =A17+1 -> 16 | B18: Purchase | C18: Bangalore WH | D18: BULK LIQUID SOLUTIONS PVT LTD | E18: =IFERROR(VLOOKUP(D18,Dropdown!A:B,2,0),D18) -> BULK LIQUID SOLUTIONS PVT LTD | F18: 45752 | G18: =TEXT(F18, "MMM-YY") -> Apr-25 | H18: B008/25-56 | I18: 95 | J18: 10000 | K18: PP RAFFIA PPH-T03 SINOPEC | L18: =VLOOKUP(K18, 'Items Master'!A:E,5,0) -> SINOPEC | M18: =VLOOKUP(K18, 'Items Master'!A:D,4,0) -> PP | N18: Outright | Q18: 45752 | R18: =TEXT(Q18, "MMM-YY") -> Apr-25 | W18: 95 | AN18: =SUM(AB18:AM18) -> 0 | AP18: =I18-W18-X18-AN18 -> 0 | AQ18: Verified & Closed
A19: =A18+1 -> 17 | B19: Purchase | C19: Bangalore WH | D19: TRIMURTI POLYCHEM PRIVATE LIMITED | E19: =IFERROR(VLOOKUP(D19,Dropdown!A:B,2,0),D19) -> TRIMURTI POLYCHEM PRIVATE LIMITED | F19: 45752 | G19: =TEXT(F19, "MMM-YY") -> Apr-25 | H19: T1250037 | I19: 91.5 | J19: 24750 | K19: HD HM EGDA 6888 EQUATE | L19: =VLOOKUP(K19, 'Items Master'!A:E,5,0) -> EQUATE | M19: =VLOOKUP(K19, 'Items Master'!A:D,4,0) -> HDPE | N19: Outright | Q19: 45752 | R19: =TEXT(Q19, "MMM-YY") -> Apr-25 | W19: 91.5 | AN19: =SUM(AB19:AM19) -> 0 | AP19: =I19-W19-X19-AN19 -> 0 | AQ19: Verified & Closed
... A29: =A28+1 -> 27 | B29: Purchase | C29: Chennai Office | D29: SQUAREFLEX PACKAGING PRIVATE LIMITED | E29: =IFERROR(VLOOKUP(D29,Dropdown!A:B,2,0),D29) -> SQUAREFLEX PACKAGING PRIVATE LIMITED | F29: 45755 | G29: =TEXT(F29, "MMM-YY") -> Apr-25 | H29: SP/17/25-26 | I29: 123.5 | J29: 10000 | K29: LDPE HEAVYDUTY 22FA002 RIL | L29: =VLOOKUP(K29, 'Items Master'!A:E,5,0) -> RIL | M29: =VLOOKUP(K29, 'Items Master'!A:D,4,0) -> LDPE | N29: Outright | Q29: 45755 | R29: =TEXT(Q29, "MMM-YY") -> Apr-25 | W29: 123.5 | AN29: =SUM(AB29:AM29) -> 0 | AP29: =I29-W29-X29-AN29 -> 0 | AQ29: Verified & Closed
A30: =A29+1 -> 28 | B30: Purchase | C30: Bangalore WH | D30: CHAKRAPANI VYAPAR PRIVATE LIMITED | E30: =IFERROR(VLOOKUP(D30,Dropdown!A:B,2,0),D30) -> CVPL | F30: 45755 | G30: =TEXT(F30, "MMM-YY") -> Apr-25 | H30: CV2526YPR000556 | I30: 98.9 | J30: 3000 | K30: PP RAFFIA HR003 MRPL | L30: =VLOOKUP(K30, 'Items Master'!A:E,5,0) -> MRPL | M30: =VLOOKUP(K30, 'Items Master'!A:D,4,0) -> PP | N30: Discounts | Q30: 45755 | R30: =TEXT(Q30, "MMM-YY") -> Apr-25 | X30: 98.9 | AN30: =SUM(AB30:AM30) -> 0 | AP30: =I30-W30-X30-AN30 -> 0 | AQ30: Open
A31: =A30+1 -> 29 | B31: Purchase | C31: Bangalore WH | D31: D R POLYMERS PRIVATE LIMITED | E31: =IFERROR(VLOOKUP(D31,Dropdown!A:B,2,0),D31) -> D R POLYMERS PRIVATE LIMITED | F31: 45755 | G31: =TEXT(F31, "MMM-YY") -> Apr-25 | H31: CN000017 | I31: 67.85 | J31: 30000 | K31: PVC SUSPENSION RESIN HS1000R | L31: =VLOOKUP(K31, 'Items Master'!A:E,5,0) -> HANWHA | M31: =VLOOKUP(K31, 'Items Master'!A:D,4,0) -> PVC | N31: Outright | Q31: 45755 | R31: =TEXT(Q31, "MMM-YY") -> Apr-25 | W31: 67.85 | AN31: =SUM(AB31:AM31) -> 0 | AP31: =I31-W31-X31-AN31 -> 0 | AQ31: Verified & Closed
A32: =A31+1 -> 30 | B32: Purchase | C32: Chennai Office | D32: IVORY POLYMERS | E32: =IFERROR(VLOOKUP(D32,Dropdown!A:B,2,0),D32) -> IVORY POLYMERS | F32: 45756 | G32: =TEXT(F32, "MMM-YY") -> Apr-25 | H32: 11 | I32: 105 | J32: 6000 | K32: PP RANDOM RE420MO BOROUGE | L32: =VLOOKUP(K32, 'Items Master'!A:E,5,0) -> BOROUGE | M32: =VLOOKUP(K32, 'Items Master'!A:D,4,0) -> PP RCP | N32: Outright | Q32: 45756 | R32: =TEXT(Q32, "MMM-YY") -> Apr-25 | W32: 105 | AN32: =SUM(AB32:AM32) -> 0 | AP32: =I32-W32-X32-AN32 -> 0 | AQ32: Verified & Closed
A33: =A32+1 -> 31 | B33: Purchase | C33: Bangalore WH | D33: INTIME VINCOM PRIVATE LIMITED | E33: =IFERROR(VLOOKUP(D33,Dropdown!A:B,2,0),D33) -> Intime | F33: 45757 | G33: =TEXT(F33, "MMM-YY") -> Apr-25 | H33: A-40/2025-26 | I33: 100.974 | J33: 13000 | K33: LLDPE F18S010UA GAIL | L33: =VLOOKUP(K33, 'Items Master'!A:E,5,0) -> GAIL | M33: =VLOOKUP(K33, 'Items Master'!A:D,4,0) -> LLDPE | N33: Discounts | Q33: 45757 | R33: =TEXT(Q33, "MMM-YY") -> Apr-25 | X33: 100.974 | AN33: =SUM(AB33:AM33) -> 0 | AP33: =I33-W33-X33-AN33 -> 0 | AQ33: Open
A34: =A33+1 -> 32 | B34: Purchase | C34: Bangalore WH | D34: SYNTHETIC PACKERS LIMITED | E34: =IFERROR(VLOOKUP(D34,Dropdown!A:B,2,0),D34) -> SYNTHETIC PACKERS LIMITED | F34: 45757 | G34: =TEXT(F34, "MMM-YY") -> Apr-25 | H34: SYN25/00144 | I34: 91.5 | J34: 10000 | K34: HD HM 6097 LUBAN | L34: =VLOOKUP(K34, 'Items Master'!A:E,5,0) -> LUBAN | M34: =VLOOKUP(K34, 'Items Master'!A:D,4,0) -> HDPE | N34: Outright | Q34: 45757 | R34: =TEXT(Q34, "MMM-YY") -> Apr-25 | W34: 91.5 | AN34: =SUM(AB34:AM34) -> 0 | AP34: =I34-W34-X34-AN34 -> 0 | AQ34: Verified & Closed
A35: =A34+1 -> 33 | B35: Purchase | C35: Chennai Office | D35: SYNTHETIC PACKERS LIMITED | E35: =IFERROR(VLOOKUP(D35,Dropdown!A:B,2,0),D35) -> SYNTHETIC PACKERS LIMITED | F35: 45757 | G35: =TEXT(F35, "MMM-YY") -> Apr-25 | H35: SYN25/00139 | I35: 91.5 | J35: 12750 | K35: HD HM 6097 LUBAN | L35: =VLOOKUP(K35, 'Items Master'!A:E,5,0) -> LUBAN | M35: =VLOOKUP(K35, 'Items Master'!A:D,4,0) -> HDPE | N35: Outright | Q35: 45757 | R35: =TEXT(Q35, "MMM-YY") -> Apr-25 | W35: 91.5 | AN35: =SUM(AB35:AM35) -> 0 | AP35: =I35-W35-X35-AN35 -> 0 | AQ35: Verified & Closed
A36: =A35+1 -> 34 | B36: Purchase | C36: Chennai Office | D36: CHAKRAPANI VYAPAR PRIVATE LIMITED | E36: =IFERROR(VLOOKUP(D36,Dropdown!A:B,2,0),D36) -> CVPL | F36: 45758 | G36: =TEXT(F36, "MMM-YY") -> Apr-25 | H36: CV2526BGP000121 | I36: 101.486 | J36: 1000 | K36: LLDPE SLIP F20S009 GAIL | L36: =VLOOKUP(K36, 'Items Master'!A:E,5,0) -> GAIL | M36: =VLOOKUP(K36, 'Items Master'!A:D,4,0) -> LLDPE | N36: Discounts | O36: With Discount | Q36: 45758 | R36: =TEXT(Q36, "MMM-YY") -> Apr-25 | X36: 100.99 | AN36: =SUM(AB36:AM36) -> 0 | AP36: =I36-W36-X36-AN36 -> 0.496 | AQ36: Open
A37: =A36+1 -> 35 | B37: Purchase | C37: Bangalore WH | D37: CHAKRAPANI VYAPAR PRIVATE LIMITED | E37: =IFERROR(VLOOKUP(D37,Dropdown!A:B,2,0),D37) -> CVPL | F37: 45758 | G37: =TEXT(F37, "MMM-YY") -> Apr-25 | H37: CV2526BGP000121 | I37: 120.75 | J37: 100 | K37: LD SLIP J24FS040 RIL | L37: =VLOOKUP(K37, 'Items Master'!A:E,5,0) -> RIL | M37: =VLOOKUP(K37, 'Items Master'!A:D,4,0) -> LDPE | N37: Outright | Q37: 45758 | R37: =TEXT(Q37, "MMM-YY") -> Apr-25 | W37: 120.75 | AN37: =SUM(AB37:AM37) -> 0 | AP37: =I37-W37-X37-AN37 -> 0 | AQ37: Verified & Closed
A38: =A37+1 -> 36 | B38: Purchase | C38: Bangalore WH | D38: TREENITY PLY DECOR | E38: =IFERROR(VLOOKUP(D38,Dropdown!A:B,2,0),D38) -> Treenity | F38: 45758 | G38: =TEXT(F38, "MMM-YY") -> Apr-25 | H38: 48 | I38: 100.55 | J38: 10000 | K38: PP RAFFIA HR003 MRPL | L38: =VLOOKUP(K38, 'Items Master'!A:E,5,0) -> MRPL | M38: =VLOOKUP(K38, 'Items Master'!A:D,4,0) -> PP | N38: Discounts | Q38: 45758 | R38: =TEXT(Q38, "MMM-YY") -> Apr-25 | U38: Plant | X38: 98.9 | Y38: Ex-Works | Z38: Bangalore | AI38: 1.65 | AN38: =SUM(AB38:AM38) -> 1.65 | AP38: =I38-W38-X38-AN38 -> -8.437695e-15 | AQ38: Verified & Closed
A39: =A38+1 -> 37 | B39: Purchase | C39: Bangalore WH | D39: SYNTHETIC PACKERS LIMITED | E39: =IFERROR(VLOOKUP(D39,Dropdown!A:B,2,0),D39) -> SYNTHETIC PACKERS LIMITED | F39: 45758 | G39: =TEXT(F39, "MMM-YY") -> Apr-25 | H39: SYN25/00185 | I39: 91.5 | J39: 24750 | K39: HD HM 6097 LUBAN | L39: =VLOOKUP(K39, 'Items Master'!A:E,5,0) -> LUBAN | M39: =VLOOKUP(K39, 'Items Master'!A:D,4,0) -> HDPE | N39: Outright | Q39: 45758 | R39: =TEXT(Q39, "MMM-YY") -> Apr-25 | W39: 91.5 | AN39: =SUM(AB39:AM39) -> 0 | AP39: =I39-W39-X39-AN39 -> 0 | AQ39: Verified & Closed
A40: =A39+1 -> 38 | B40: Purchase | C40: Chennai Office | D40: SYNTHETIC PACKERS LIMITED | E40: =IFERROR(VLOOKUP(D40,Dropdown!A:B,2,0),D40) -> SYNTHETIC PACKERS LIMITED | F40: 45758 | G40: =TEXT(F40, "MMM-YY") -> Apr-25 | H40: SYN25/00186 | I40: 91.5 | J40: 2000 | K40: HD HM 6097 LUBAN | L40: =VLOOKUP(K40, 'Items Master'!A:E,5,0) -> LUBAN | M40: =VLOOKUP(K40, 'Items Master'!A:D,4,0) -> HDPE | N40: Outright | Q40: 45758 | R40: =TEXT(Q40, "MMM-YY") -> Apr-25 | W40: 91.5 | AN40: =SUM(AB40:AM40) -> 0 | AP40: =I40-W40-X40-AN40 -> 0 | AQ40: Verified & Closed
A41: =A40+1 -> 39 | B41: Purchase | C41: Chennai Office | D41: SYNTHETIC PACKERS LIMITED | E41: =IFERROR(VLOOKUP(D41,Dropdown!A:B,2,0),D41) -> SYNTHETIC PACKERS LIMITED | F41: 45758 | G41: =TEXT(F41, "MMM-YY") -> Apr-25 | H41: SYN25/00186 | I41: 91.25 | J41: 10000 | K41: HD HM 6097 LUBAN | L41: =VLOOKUP(K41, 'Items Master'!A:E,5,0) -> LUBAN | M41: =VLOOKUP(K41, 'Items Master'!A:D,4,0) -> HDPE | N41: Outright | Q41: 45758 | R41: =TEXT(Q41, "MMM-YY") -> Apr-25 | W41: 91.25 | AN41: =SUM(AB41:AM41) -> 0 | AP41: =I41-W41-X41-AN41 -> 0 | AQ41: Verified & Closed
A42: =A41+1 -> 40 | B42: Purchase | C42: Bangalore WH | D42: PRESTINE VENTURES PRIVATE LIMITED | E42: =IFERROR(VLOOKUP(D42,Dropdown!A:B,2,0),D42) -> Prestine | F42: 45759 | G42: =TEXT(F42, "MMM-YY") -> Apr-25 | H42: HYD/82 | I42: 101.74 | J42: 10000 | K42: PP RAFFIA H030SG RIL | L42: =VLOOKUP(K42, 'Items Master'!A:E,5,0) -> RIL | M42: =VLOOKUP(K42, 'Items Master'!A:D,4,0) -> PP | N42: Discounts | Q42: 45759 | R42: =TEXT(Q42, "MMM-YY") -> Apr-25 | X42: 101.74 | Y42: Ex-DCA-Depo | Z42: Hyderabad | AN42: =SUM(AB42:AM42) -> 0 | AP42: =I42-W42-X42-AN42 -> 0 | AQ42: Verified & Closed
A43: =A42+1 -> 41 | B43: Purchase | C43: Bangalore WH | D43: PARAGON RESIN LLP | E43: =IFERROR(VLOOKUP(D43,Dropdown!A:B,2,0),D43) -> Paragon | F43: 45759 | G43: =TEXT(F43, "MMM-YY") -> Apr-25 | H43: MNG/030 | I43: 100.28 | J43: 25000 | K43: PP RAFFIA H030SG RIL | L43: =VLOOKUP(K43, 'Items Master'!A:E,5,0) -> RIL | M43: =VLOOKUP(K43, 'Items Master'!A:D,4,0) -> PP | N43: Discounts | Q43: 45759 | R43: =TEXT(Q43, "MMM-YY") -> Apr-25 | X43: 100.28 | AN43: =SUM(AB43:AM43) -> 0 | AP43: =I43-W43-X43-AN43 -> 0 | AQ43: Open
A44: =A43+1 -> 42 | B44: Purchase | C44: Bangalore WH | D44: INTIME VINCOM PRIVATE LIMITED | E44: =IFERROR(VLOOKUP(D44,Dropdown!A:B,2,0),D44) -> Intime | F44: 45759 | G44: =TEXT(F44, "MMM-YY") -> Apr-25 | H44: A-61/2025-26 | I44: 99.933 | J44: 12000 | K44: LLDPE SLIP F20S010IA BCPL | L44: =VLOOKUP(K44, 'Items Master'!A:E,5,0) -> BCPL | M44: =VLOOKUP(K44, 'Items Master'!A:D,4,0) -> LLDPE | N44: Discounts | Q44: 45759 | R44: =TEXT(Q44, "MMM-YY") -> Apr-25 | X44: 99.933 | AN44: =SUM(AB44:AM44) -> 0 | AP44: =I44-W44-X44-AN44 -> 0 | AQ44: Open
A45: =A44+1 -> 43 | B45: Purchase | C45: Bangalore WH | D45: PARAGON RESIN LLP | E45: =IFERROR(VLOOKUP(D45,Dropdown!A:B,2,0),D45) -> Paragon | F45: 45759 | G45: =TEXT(F45, "MMM-YY") -> Apr-25 | H45: 263 | I45: 102.8 | J45: 1000 | K45: PP TQ H100EY RIL | L45: =VLOOKUP(K45, 'Items Master'!A:E,5,0) -> RIL | M45: =VLOOKUP(K45, 'Items Master'!A:D,4,0) -> PP | N45: Discounts | Q45: 45759 | R45: =TEXT(Q45, "MMM-YY") -> Apr-25 | X45: 102.8 | AN45: =SUM(AB45:AM45) -> 0 | AP45: =I45-W45-X45-AN45 -> 0 | AQ45: Open
A46: =A45+1 -> 44 | B46: Purchase | C46: Bangalore WH | D46: PARAGON RESIN LLP | E46: =IFERROR(VLOOKUP(D46,Dropdown!A:B,2,0),D46) -> Paragon | F46: 45759 | G46: =TEXT(F46, "MMM-YY") -> Apr-25 | H46: 252 | I46: 102.8 | J46: 2000 | K46: HDPE RAFFIA HD55EF010 RIL | L46: =VLOOKUP(K46, 'Items Master'!A:E,5,0) -> RIL | M46: =VLOOKUP(K46, 'Items Master'!A:D,4,0) -> HDPE | N46: Discounts | Q46: 45759 | R46: =TEXT(Q46, "MMM-YY") -> Apr-25 | X46: 102.8 | AN46: =SUM(AB46:AM46) -> 0 | AP46: =I46-W46-X46-AN46 -> 0 | AQ46: Open
A47: =A46+1 -> 45 | B47: Purchase | C47: Bangalore WH | D47: LPB Plastic Private Limited | E47: =IFERROR(VLOOKUP(D47,Dropdown!A:B,2,0),D47) -> LPB Plastic Private Limited | F47: 45759 | G47: =TEXT(F47, "MMM-YY") -> Apr-25 | H47: RM/084/25-26 | I47: 98.5 | J47: 12000 | K47: LLDPE NON-SLIP F0218L HMEL | L47: =VLOOKUP(K47, 'Items Master'!A:E,5,0) -> HMEL | M47: =VLOOKUP(K47, 'Items Master'!A:D,4,0) -> LLDPE | N47: Outright | Q47: 45759 | R47: =TEXT(Q47, "MMM-YY") -> Apr-25 | W47: 98.5 | AN47: =SUM(AB47:AM47) -> 0 | AP47: =I47-W47-X47-AN47 -> 0 | AQ47: Verified & Closed
A48: =A47+1 -> 46 | B48: Purchase | C48: Bangalore WH | D48: CHAKRAPANI VYAPAR PRIVATE LIMITED | E48: =IFERROR(VLOOKUP(D48,Dropdown!A:B,2,0),D48) -> CVPL | F48: 45759 | G48: =TEXT(F48, "MMM-YY") -> Apr-25 | H48: CV2526YPR000886 | I48: 97.5 | J48: 2000 | K48: LLDPE SLIP JF19010 RIL | L48: =VLOOKUP(K48, 'Items Master'!A:E,5,0) -> RIL | M48: =VLOOKUP(K48, 'Items Master'!A:D,4,0) -> LLDPE | N48: Outright | Q48: 45759 | R48: =TEXT(Q48, "MMM-YY") -> Apr-25 | W48: 97.5 | AN48: =SUM(AB48:AM48) -> 0 | AP48: =I48-W48-X48-AN48 -> 0 | AQ48: Verified & Closed
A49: =A48+1 -> 47 | B49: Purchase | C49: Bangalore WH | D49: PARAGON RESIN LLP | E49: =IFERROR(VLOOKUP(D49,Dropdown!A:B,2,0),D49) -> Paragon | F49: 45759 | G49: =TEXT(F49, "MMM-YY") -> Apr-25 | H49: 267 | I49: 106.28 | J49: 5000 | K49: PP LAMINATION H350EC RIL | L49: =VLOOKUP(K49, 'Items Master'!A:E,5,0) -> RIL | M49: =VLOOKUP(K49, 'Items Master'!A:D,4,0) -> PP | N49: Discounts | Q49: 45759 | R49: =TEXT(Q49, "MMM-YY") -> Apr-25 | X49: 106.28 | AN49: =SUM(AB49:AM49) -> 0 | AP49: =I49-W49-X49-AN49 -> 0 | AQ49: Open
...

Sheet Supplier Wise Monthly
A1: Month | B1: 45870 | F1: =SUMIFS('<< Working >>'!J:J, '<< Working >>'!R:R, 'Supplier Wise Monthly'!B1, '<< Working >>'!D:D, 'Supplier Wise Monthly'!B2)-F4 -> 0 | G1: Check
A2: Supplier | B2: KAMAKYA CHEMPLAST PRIVATE LIMITED
C4: =SUM(C7:C66) -> 105000 | D4: =SUM(D7:D66) -> 0 | E4: =SUM(E7:E66) -> 0 | F4: =SUM(F7:F66) -> 105000 | G4: Total
C5: =SUBTOTAL(9, C7:C66) -> 105000 | D5: =SUBTOTAL(9, D7:D66) -> 0 | E5: =SUBTOTAL(9, E7:E66) -> 0 | F5: =SUM(C5:E5) -> 105000 | G5: Sub-Total
A6: Type | B6: Company | C6: Discounts | D6: Outright with Discounts | E6: Outright | F6: Total
A7: =VLOOKUP(B7, 'Items Master'!E:F,2,0) -> Domestic | B7: IOCL | C7: =SUMIFS('<< Working >>'!$J:$J, '<< Working >>'!$D:$D, 'Supplier Wise Monthly'!$B$2, '<< Working >>'!$L:$L, 'Supplier Wise Monthly'!$B7, '<< Working >>'!$N:$N, 'Supplier Wise Monthly'!C$6, '<< Working >>'!$R:$R, 'Supplier Wise Monthly'!$B$1) -> 0 | D7: =SUMIFS('<< Working >>'!$J:$J, '<< Working >>'!$D:$D, 'Supplier Wise Monthly'!$B$2, '<< Working >>'!$L:$L, 'Supplier Wise Monthly'!$B7, '<< Working >>'!$N:$N, 'Supplier Wise Monthly'!D$6, '<< Working >>'!$R:$R, 'Supplier Wise Monthly'!$B$1) -> 0 | E7: =SUMIFS('<< Working >>'!$J:$J, '<< Working >>'!$D:$D, 'Supplier Wise Monthly'!$B$2, '<< Working >>'!$L:$L, 'Supplier Wise Monthly'!$B7, '<< Working >>'!$N:$N, 'Supplier Wise Monthly'!E$6, '<< Working >>'!$R:$R, 'Supplier Wise Monthly'!$B$1) -> 0 | F7: =SUM(C7:E7) -> 0
A8: =VLOOKUP(B8, 'Items Master'!E:F,2,0) -> Domestic | B8: HMEL | C8: =SUMIFS('<< Working >>'!$J:$J, '<< Working >>'!$D:$D, 'Supplier Wise Monthly'!$B$2, '<< Working >>'!$L:$L, 'Supplier Wise Monthly'!$B8, '<< Working >>'!$N:$N, 'Supplier Wise Monthly'!C$6, '<< Working >>'!$R:$R, 'Supplier Wise Monthly'!$B$1) -> 0 | D8: =SUMIFS('<< Working >>'!$J:$J, '<< Working >>'!$D:$D, 'Supplier Wise Monthly'!$B$2, '<< Working >>'!$L:$L, 'Supplier Wise Monthly'!$B8, '<< Working >>'!$N:$N, 'Supplier Wise Monthly'!D$6, '<< Working >>'!$R:$R, 'Supplier Wise Monthly'!$B$1) -> 0 | E8: =SUMIFS('<< Working >>'!$J:$J, '<< Working >>'!$D:$D, 'Supplier Wise Monthly'!$B$2, '<< Working >>'!$L:$L, 'Supplier Wise Monthly'!$B8, '<< Working >>'!$N:$N, 'Supplier Wise Monthly'!E$6, '<< Working >>'!$R:$R, 'Supplier Wise Monthly'!$B$1) -> 0 | F8: =SUM(C8:E8) -> 0
A9: =VLOOKUP(B9, 'Items Master'!E:F,2,0) -> Domestic | B9: MRPL | C9: =SUMIFS('<< Working >>'!$J:$J, '<< Working >>'!$D:$D, 'Supplier Wise Monthly'!$B$2, '<< Working >>'!$L:$L, 'Supplier Wise Monthly'!$B9, '<< Working >>'!$N:$N, 'Supplier Wise Monthly'!C$6, '<< Working >>'!$R:$R, 'Supplier Wise Monthly'!$B$1) -> 105000 | D9: =SUMIFS('<< Working >>'!$J:$J, '<< Working >>'!$D:$D, 'Supplier Wise Monthly'!$B$2, '<< Working >>'!$L:$L, 'Supplier Wise Monthly'!$B9, '<< Working >>'!$N:$N, 'Supplier Wise Monthly'!D$6, '<< Working >>'!$R:$R, 'Supplier Wise Monthly'!$B$1) -> 0 | E9: =SUMIFS('<< Working >>'!$J:$J, '<< Working >>'!$D:$D, 'Supplier Wise Monthly'!$B$2, '<< Working >>'!$L:$L, 'Supplier Wise Monthly'!$B9, '<< Working >>'!$N:$N, 'Supplier Wise Monthly'!E$6, '<< Working >>'!$R:$R, 'Supplier Wise Monthly'!$B$1) -> 0 | F9: =SUM(C9:E9) -> 105000
A10: =VLOOKUP(B10, 'Items Master'!E:F,2,0) -> Domestic | B10: GAIL | C10: =SUMIFS('<< Working >>'!$J:$J, '<< Working >>'!$D:$D, 'Supplier Wise Monthly'!$B$2, '<< Working >>'!$L:$L, 'Supplier Wise Monthly'!$B10, '<< Working >>'!$N:$N, 'Supplier Wise Monthly'!C$6, '<< Working >>'!$R:$R, 'Supplier Wise Monthly'!$B$1) -> 0 | D10: =SUMIFS('<< Working >>'!$J:$J, '<< Working >>'!$D:$D, 'Supplier Wise Monthly'!$B$2, '<< Working >>'!$L:$L, 'Supplier Wise Monthly'!$B10, '<< Working >>'!$N:$N, 'Supplier Wise Monthly'!D$6, '<< Working >>'!$R:$R, 'Supplier Wise Monthly'!$B$1) -> 0 | E10: =SUMIFS('<< Working >>'!$J:$J, '<< Working >>'!$D:$D, 'Supplier Wise Monthly'!$B$2, '<< Working >>'!$L:$L, 'Supplier Wise Monthly'!$B10, '<< Working >>'!$N:$N, 'Supplier Wise Monthly'!E$6, '<< Working >>'!$R:$R, 'Supplier Wise Monthly'!$B$1) -> 0 | F10: =SUM(C10:E10) -> 0
A11: =VLOOKUP(B11, 'Items Master'!E:F,2,0) -> Domestic | B11: BCPL | C11: =SUMIFS('<< Working >>'!$J:$J, '<< Working >>'!$D:$D, 'Supplier Wise Monthly'!$B$2, '<< Working >>'!$L:$L, 'Supplier Wise Monthly'!$B11, '<< Working >>'!$N:$N, 'Supplier Wise Monthly'!C$6, '<< Working >>'!$R:$R, 'Supplier Wise Monthly'!$B$1) -> 0 | D11: =SUMIFS('<< Working >>'!$J:$J, '<< Working >>'!$D:$D, 'Supplier Wise Monthly'!$B$2, '<< Working >>'!$L:$L, 'Supplier Wise Monthly'!$B11, '<< Working >>'!$N:$N, 'Supplier Wise Monthly'!D$6, '<< Working >>'!$R:$R, 'Supplier Wise Monthly'!$B$1) -> 0 | E11: =SUMIFS('<< Working >>'!$J:$J, '<< Working >>'!$D:$D, 'Supplier Wise Monthly'!$B$2, '<< Working >>'!$L:$L, 'Supplier Wise Monthly'!$B11, '<< Working >>'!$N:$N, 'Supplier Wise Monthly'!E$6, '<< Working >>'!$R:$R, 'Supplier Wise Monthly'!$B$1) -> 0 | F11: =SUM(C11:E11) -> 0
A12: =VLOOKUP(B12, 'Items Master'!E:F,2,0) -> Domestic | B12: OPAL | C12: =SUMIFS('<< Working >>'!$J:$J, '<< Working >>'!$D:$D, 'Supplier Wise Monthly'!$B$2, '<< Working >>'!$L:$L, 'Supplier Wise Monthly'!$B12, '<< Working >>'!$N:$N, 'Supplier Wise Monthly'!C$6, '<< Working >>'!$R:$R, 'Supplier Wise Monthly'!$B$1) -> 0 | D12: =SUMIFS('<< Working >>'!$J:$J, '<< Working >>'!$D:$D, 'Supplier Wise Monthly'!$B$2, '<< Working >>'!$L:$L, 'Supplier Wise Monthly'!$B12, '<< Working >>'!$N:$N, 'Supplier Wise Monthly'!D$6, '<< Working >>'!$R:$R, 'Supplier Wise Monthly'!$B$1) -> 0 | E12: =SUMIFS('<< Working >>'!$J:$J, '<< Working >>'!$D:$D, 'Supplier Wise Monthly'!$B$2, '<< Working >>'!$L:$L, 'Supplier Wise Monthly'!$B12, '<< Working >>'!$N:$N, 'Supplier Wise Monthly'!E$6, '<< Working >>'!$R:$R, 'Supplier Wise Monthly'!$B$1) -> 0 | F12: =SUM(C12:E12) -> 0
A13: =VLOOKUP(B13, 'Items Master'!E:F,2,0) -> Domestic | B13: RIL | C13: =SUMIFS('<< Working >>'!$J:$J, '<< Working >>'!$D:$D, 'Supplier Wise Monthly'!$B$2, '<< Working >>'!$L:$L, 'Supplier Wise Monthly'!$B13, '<< Working >>'!$N:$N, 'Supplier Wise Monthly'!C$6, '<< Working >>'!$R:$R, 'Supplier Wise Monthly'!$B$1) -> 0 | D13: =SUMIFS('<< Working >>'!$J:$J, '<< Working >>'!$D:$D, 'Supplier Wise Monthly'!$B$2, '<< Working >>'!$L:$L, 'Supplier Wise Monthly'!$B13, '<< Working >>'!$N:$N, 'Supplier Wise Monthly'!D$6, '<< Working >>'!$R:$R, 'Supplier Wise Monthly'!$B$1) -> 0 | E13: =SUMIFS('<< Working >>'!$J:$J, '<< Working >>'!$D:$D, 'Supplier Wise Monthly'!$B$2, '<< Working >>'!$L:$L, 'Supplier Wise Monthly'!$B13, '<< Working >>'!$N:$N, 'Supplier Wise Monthly'!E$6, '<< Working >>'!$R:$R, 'Supplier Wise Monthly'!$B$1) -> 0 | F13: =SUM(C13:E13) -> 0
A14: =VLOOKUP(B14, 'Items Master'!E:F,2,0) -> Domestic | B14: HALDIA | C14: =SUMIFS('<< Working >>'!$J:$J, '<< Working >>'!$D:$D, 'Supplier Wise Monthly'!$B$2, '<< Working >>'!$L:$L, 'Supplier Wise Monthly'!$B14, '<< Working >>'!$N:$N, 'Supplier Wise Monthly'!C$6, '<< Working >>'!$R:$R, 'Supplier Wise Monthly'!$B$1) -> 0 | D14: =SUMIFS('<< Working >>'!$J:$J, '<< Working >>'!$D:$D, 'Supplier Wise Monthly'!$B$2, '<< Working >>'!$L:$L, 'Supplier Wise Monthly'!$B14, '<< Working >>'!$N:$N, 'Supplier Wise Monthly'!D$6, '<< Working >>'!$R:$R, 'Supplier Wise Monthly'!$B$1) -> 0 | E14: =SUMIFS('<< Working >>'!$J:$J, '<< Working >>'!$D:$D, 'Supplier Wise Monthly'!$B$2, '<< Working >>'!$L:$L, 'Supplier Wise Monthly'!$B14, '<< Working >>'!$N:$N, 'Supplier Wise Monthly'!E$6, '<< Working >>'!$R:$R, 'Supplier Wise Monthly'!$B$1) -> 0 | F14: =SUM(C14:E14) -> 0
A15: =VLOOKUP(B15, 'Items Master'!E:F,2,0) -> Import | B15: MARLEX | C15: =SUMIFS('<< Working >>'!$J:$J, '<< Working >>'!$D:$D, 'Supplier Wise Monthly'!$B$2, '<< Working >>'!$L:$L, 'Supplier Wise Monthly'!$B15, '<< Working >>'!$N:$N, 'Supplier Wise Monthly'!C$6, '<< Working >>'!$R:$R, 'Supplier Wise Monthly'!$B$1) -> 0 | D15: =SUMIFS('<< Working >>'!$J:$J, '<< Working >>'!$D:$D, 'Supplier Wise Monthly'!$B$2, '<< Working >>'!$L:$L, 'Supplier Wise Monthly'!$B15, '<< Working >>'!$N:$N, 'Supplier Wise Monthly'!D$6, '<< Working >>'!$R:$R, 'Supplier Wise Monthly'!$B$1) -> 0 | E15: =SUMIFS('<< Working >>'!$J:$J, '<< Working >>'!$D:$D, 'Supplier Wise Monthly'!$B$2, '<< Working >>'!$L:$L, 'Supplier Wise Monthly'!$B15, '<< Working >>'!$N:$N, 'Supplier Wise Monthly'!E$6, '<< Working >>'!$R:$R, 'Supplier Wise Monthly'!$B$1) -> 0 | F15: =SUM(C15:E15) -> 0
A16: =VLOOKUP(B16, 'Items Master'!E:F,2,0) -> Import | B16: LOTRENE | C16: =SUMIFS('<< Working >>'!$J:$J, '<< Working >>'!$D:$D, 'Supplier Wise Monthly'!$B$2, '<< Working >>'!$L:$L, 'Supplier Wise Monthly'!$B16, '<< Working >>'!$N:$N, 'Supplier Wise Monthly'!C$6, '<< Working >>'!$R:$R, 'Supplier Wise Monthly'!$B$1) -> 0 | D16: =SUMIFS('<< Working >>'!$J:$J, '<< Working >>'!$D:$D, 'Supplier Wise Monthly'!$B$2, '<< Working >>'!$L:$L, 'Supplier Wise Monthly'!$B16, '<< Working >>'!$N:$N, 'Supplier Wise Monthly'!D$6, '<< Working >>'!$R:$R, 'Supplier Wise Monthly'!$B$1) -> 0 | E16: =SUMIFS('<< Working >>'!$J:$J, '<< Working >>'!$D:$D, 'Supplier Wise Monthly'!$B$2, '<< Working >>'!$L:$L, 'Supplier Wise Monthly'!$B16, '<< Working >>'!$N:$N, 'Supplier Wise Monthly'!E$6, '<< Working >>'!$R:$R, 'Supplier Wise Monthly'!$B$1) -> 0 | F16: =SUM(C16:E16) -> 0
A17: =VLOOKUP(B17, 'Items Master'!E:F,2,0) -> Import | B17: EXXON | C17: =SUMIFS('<< Working >>'!$J:$J, '<< Working >>'!$D:$D, 'Supplier Wise Monthly'!$B$2, '<< Working >>'!$L:$L, 'Supplier Wise Monthly'!$B17, '<< Working >>'!$N:$N, 'Supplier Wise Monthly'!C$6, '<< Working >>'!$R:$R, 'Supplier Wise Monthly'!$B$1) -> 0 | D17: =SUMIFS('<< Working >>'!$J:$J, '<< Working >>'!$D:$D, 'Supplier Wise Monthly'!$B$2, '<< Working >>'!$L:$L, 'Supplier Wise Monthly'!$B17, '<< Working >>'!$N:$N, 'Supplier Wise Monthly'!D$6, '<< Working >>'!$R:$R, 'Supplier Wise Monthly'!$B$1) -> 0 | E17: =SUMIFS('<< Working >>'!$J:$J, '<< Working >>'!$D:$D, 'Supplier Wise Monthly'!$B$2, '<< Working >>'!$L:$L, 'Supplier Wise Monthly'!$B17, '<< Working >>'!$N:$N, 'Supplier Wise Monthly'!E$6, '<< Working >>'!$R:$R, 'Supplier Wise Monthly'!$B$1) -> 0 | F17: =SUM(C17:E17) -> 0
A18: =VLOOKUP(B18, 'Items Master'!E:F,2,0) -> Import | B18: DOW | C18: =SUMIFS('<< Working >>'!$J:$J, '<< Working >>'!$D:$D, 'Supplier Wise Monthly'!$B$2, '<< Working >>'!$L:$L, 'Supplier Wise Monthly'!$B18, '<< Working >>'!$N:$N, 'Supplier Wise Monthly'!C$6, '<< Working >>'!$R:$R, 'Supplier Wise Monthly'!$B$1) -> 0 | D18: =SUMIFS('<< Working >>'!$J:$J, '<< Working >>'!$D:$D, 'Supplier Wise Monthly'!$B$2, '<< Working >>'!$L:$L, 'Supplier Wise Monthly'!$B18, '<< Working >>'!$N:$N, 'Supplier Wise Monthly'!D$6, '<< Working >>'!$R:$R, 'Supplier Wise Monthly'!$B$1) -> 0 | E18: =SUMIFS('<< Working >>'!$J:$J, '<< Working >>'!$D:$D, 'Supplier Wise Monthly'!$B$2, '<< Working >>'!$L:$L, 'Supplier Wise Monthly'!$B18, '<< Working >>'!$N:$N, 'Supplier Wise Monthly'!E$6, '<< Working >>'!$R:$R, 'Supplier Wise Monthly'!$B$1) -> 0 | F18: =SUM(C18:E18) -> 0
... A66: =VLOOKUP(B66, 'Items Master'!E:F,2,0) -> Import | B66: TAIRISAN | C66: =SUMIFS('<< Working >>'!$J:$J, '<< Working >>'!$D:$D, 'Supplier Wise Monthly'!$B$2, '<< Working >>'!$L:$L, 'Supplier Wise Monthly'!$B66, '<< Working >>'!$N:$N, 'Supplier Wise Monthly'!C$6, '<< Working >>'!$R:$R, 'Supplier Wise Monthly'!$B$1) -> 0 | D66: =SUMIFS('<< Working >>'!$J:$J, '<< Working >>'!$D:$D, 'Supplier Wise Monthly'!$B$2, '<< Working >>'!$L:$L, 'Supplier Wise Monthly'!$B66, '<< Working >>'!$N:$N, 'Supplier Wise Monthly'!D$6, '<< Working >>'!$R:$R, 'Supplier Wise Monthly'!$B$1) -> 0 | E66: =SUMIFS('<< Working >>'!$J:$J, '<< Working >>'!$D:$D, 'Supplier Wise Monthly'!$B$2, '<< Working >>'!$L:$L, 'Supplier Wise Monthly'!$B66, '<< Working >>'!$N:$N, 'Supplier Wise Monthly'!E$6, '<< Working >>'!$R:$R, 'Supplier Wise Monthly'!$B$1) -> 0 | F66: =SUM(C66:E66) -> 0

Sheet Supplier Wise Yearly
A1: Supplier Name | B1: CHAKRAPANI VYAPAR PRIVATE LIMITED | O1: =SUMIFS('<< Working >>'!J:J, '<< Working >>'!D:D, 'Supplier Wise Yearly'!B1, '<< Working >>'!N:N, 'Supplier Wise Yearly'!B2)-O4 -> 0 | P1: Check
A2: Type | B2: Discounts
C4: =SUM(C7:C66) -> 7750 | D4: =SUM(D7:D66) -> 163750 | E4: =SUM(E7:E66) -> 79500 | F4: =SUM(F7:F66) -> 136250 | G4: =SUM(G7:G66) -> 133000 | H4: =SUM(H7:H66) -> 142500 | I4: =SUM(I7:I66) -> 211750 | J4: =SUM(J7:J66) -> 69500 | ... N4: =SUM(N7:N66) -> 0 | O4: =SUM(C4:N4) -> 944000 | P4: Total
C5: =SUBTOTAL(9, C7:C66) -> 7750 | D5: =SUBTOTAL(9, D7:D66) -> 163750 | E5: =SUBTOTAL(9, E7:E66) -> 79500 | F5: =SUBTOTAL(9, F7:F66) -> 136250 | G5: =SUBTOTAL(9, G7:G66) -> 133000 | H5: =SUBTOTAL(9, H7:H66) -> 142500 | I5: =SUBTOTAL(9, I7:I66) -> 211750 | J5: =SUBTOTAL(9, J7:J66) -> 69500 | ... N5: =SUBTOTAL(9, N7:N66) -> 0 | O5: =SUM(C5:N5) -> 944000 | P5: Sub-Total
A6: Type | B6: Company | C6: 45748 | D6: 45778 | E6: 45809 | F6: 45839 | G6: 45870 | H6: 45901 | I6: 45931 | J6: 45962 | K6: 45992 | L6: 46023 | M6: 46054 | N6: 46082 | O6: Total | Q6: Qty
A7: =VLOOKUP(B7, 'Items Master'!E:F,2,0) -> Domestic | B7: IOCL | C7: =SUMIFS('<< Working >>'!$J:$J, '<< Working >>'!$D:$D, 'Supplier Wise Yearly'!$B$1, '<< Working >>'!$R:$R, 'Supplier Wise Yearly'!C$6, '<< Working >>'!$L:$L, 'Supplier Wise Yearly'!$B7, '<< Working >>'!$N:$N, 'Supplier Wise Yearly'!$B$2) -> 0 | D7: =SUMIFS('<< Working >>'!$J:$J, '<< Working >>'!$D:$D, 'Supplier Wise Yearly'!$B$1, '<< Working >>'!$R:$R, 'Supplier Wise Yearly'!D$6, '<< Working >>'!$L:$L, 'Supplier Wise Yearly'!$B7, '<< Working >>'!$N:$N, 'Supplier Wise Yearly'!$B$2) -> 0 | E7: =SUMIFS('<< Working >>'!$J:$J, '<< Working >>'!$D:$D, 'Supplier Wise Yearly'!$B$1, '<< Working >>'!$R:$R, 'Supplier Wise Yearly'!E$6, '<< Working >>'!$L:$L, 'Supplier Wise Yearly'!$B7, '<< Working >>'!$N:$N, 'Supplier Wise Yearly'!$B$2) -> 0 | F7: =SUMIFS('<< Working >>'!$J:$J, '<< Working >>'!$D:$D, 'Supplier Wise Yearly'!$B$1, '<< Working >>'!$R:$R, 'Supplier Wise Yearly'!F$6, '<< Working >>'!$L:$L, 'Supplier Wise Yearly'!$B7, '<< Working >>'!$N:$N, 'Supplier Wise Yearly'!$B$2) -> 0 | G7: =SUMIFS('<< Working >>'!$J:$J, '<< Working >>'!$D:$D, 'Supplier Wise Yearly'!$B$1, '<< Working >>'!$R:$R, 'Supplier Wise Yearly'!G$6, '<< Working >>'!$L:$L, 'Supplier Wise Yearly'!$B7, '<< Working >>'!$N:$N, 'Supplier Wise Yearly'!$B$2) -> 0 | H7: =SUMIFS('<< Working >>'!$J:$J, '<< Working >>'!$D:$D, 'Supplier Wise Yearly'!$B$1, '<< Working >>'!$R:$R, 'Supplier Wise Yearly'!H$6, '<< Working >>'!$L:$L, 'Supplier Wise Yearly'!$B7, '<< Working >>'!$N:$N, 'Supplier Wise Yearly'!$B$2) -> 0 | I7: =SUMIFS('<< Working >>'!$J:$J, '<< Working >>'!$D:$D, 'Supplier Wise Yearly'!$B$1, '<< Working >>'!$R:$R, 'Supplier Wise Yearly'!I$6, '<< Working >>'!$L:$L, 'Supplier Wise Yearly'!$B7, '<< Working >>'!$N:$N, 'Supplier Wise Yearly'!$B$2) -> 0 | J7: =SUMIFS('<< Working >>'!$J:$J, '<< Working >>'!$D:$D, 'Supplier Wise Yearly'!$B$1, '<< Working >>'!$R:$R, 'Supplier Wise Yearly'!J$6, '<< Working >>'!$L:$L, 'Supplier Wise Yearly'!$B7, '<< Working >>'!$N:$N, 'Supplier Wise Yearly'!$B$2) -> 0 | ... N7: =SUMIFS('<< Working >>'!$J:$J, '<< Working >>'!$D:$D, 'Supplier Wise Yearly'!$B$1, '<< Working >>'!$R:$R, 'Supplier Wise Yearly'!N$6, '<< Working >>'!$L:$L, 'Supplier Wise Yearly'!$B7, '<< Working >>'!$N:$N, 'Supplier Wise Yearly'!$B$2) -> 0 | O7: =SUM(C7:N7) -> 0 | Q7: =IF(O7>0, "Yes", "No") -> No
A8: =VLOOKUP(B8, 'Items Master'!E:F,2,0) -> Domestic | B8: HMEL | C8: =SUMIFS('<< Working >>'!$J:$J, '<< Working >>'!$D:$D, 'Supplier Wise Yearly'!$B$1, '<< Working >>'!$R:$R, 'Supplier Wise Yearly'!C$6, '<< Working >>'!$L:$L, 'Supplier Wise Yearly'!$B8, '<< Working >>'!$N:$N, 'Supplier Wise Yearly'!$B$2) -> 0 | D8: =SUMIFS('<< Working >>'!$J:$J, '<< Working >>'!$D:$D, 'Supplier Wise Yearly'!$B$1, '<< Working >>'!$R:$R, 'Supplier Wise Yearly'!D$6, '<< Working >>'!$L:$L, 'Supplier Wise Yearly'!$B8, '<< Working >>'!$N:$N, 'Supplier Wise Yearly'!$B$2) -> 0 | E8: =SUMIFS('<< Working >>'!$J:$J, '<< Working >>'!$D:$D, 'Supplier Wise Yearly'!$B$1, '<< Working >>'!$R:$R, 'Supplier Wise Yearly'!E$6, '<< Working >>'!$L:$L, 'Supplier Wise Yearly'!$B8, '<< Working >>'!$N:$N, 'Supplier Wise Yearly'!$B$2) -> 0 | F8: =SUMIFS('<< Working >>'!$J:$J, '<< Working >>'!$D:$D, 'Supplier Wise Yearly'!$B$1, '<< Working >>'!$R:$R, 'Supplier Wise Yearly'!F$6, '<< Working >>'!$L:$L, 'Supplier Wise Yearly'!$B8, '<< Working >>'!$N:$N, 'Supplier Wise Yearly'!$B$2) -> 0 | G8: =SUMIFS('<< Working >>'!$J:$J, '<< Working >>'!$D:$D, 'Supplier Wise Yearly'!$B$1, '<< Working >>'!$R:$R, 'Supplier Wise Yearly'!G$6, '<< Working >>'!$L:$L, 'Supplier Wise Yearly'!$B8, '<< Working >>'!$N:$N, 'Supplier Wise Yearly'!$B$2) -> 0 | H8: =SUMIFS('<< Working >>'!$J:$J, '<< Working >>'!$D:$D, 'Supplier Wise Yearly'!$B$1, '<< Working >>'!$R:$R, 'Supplier Wise Yearly'!H$6, '<< Working >>'!$L:$L, 'Supplier Wise Yearly'!$B8, '<< Working >>'!$N:$N, 'Supplier Wise Yearly'!$B$2) -> 0 | I8: =SUMIFS('<< Working >>'!$J:$J, '<< Working >>'!$D:$D, 'Supplier Wise Yearly'!$B$1, '<< Working >>'!$R:$R, 'Supplier Wise Yearly'!I$6, '<< Working >>'!$L:$L, 'Supplier Wise Yearly'!$B8, '<< Working >>'!$N:$N, 'Supplier Wise Yearly'!$B$2) -> 0 | J8: =SUMIFS('<< Working >>'!$J:$J, '<< Working >>'!$D:$D, 'Supplier Wise Yearly'!$B$1, '<< Working >>'!$R:$R, 'Supplier Wise Yearly'!J$6, '<< Working >>'!$L:$L, 'Supplier Wise Yearly'!$B8, '<< Working >>'!$N:$N, 'Supplier Wise Yearly'!$B$2) -> 0 | ... N8: =SUMIFS('<< Working >>'!$J:$J, '<< Working >>'!$D:$D, 'Supplier Wise Yearly'!$B$1, '<< Working >>'!$R:$R, 'Supplier Wise Yearly'!N$6, '<< Working >>'!$L:$L, 'Supplier Wise Yearly'!$B8, '<< Working >>'!$N:$N, 'Supplier Wise Yearly'!$B$2) -> 0 | O8: =SUM(C8:N8) -> 0 | Q8: =IF(O8>0, "Yes", "No") -> No
A9: =VLOOKUP(B9, 'Items Master'!E:F,2,0) -> Domestic | B9: MRPL | C9: =SUMIFS('<< Working >>'!$J:$J, '<< Working >>'!$D:$D, 'Supplier Wise Yearly'!$B$1, '<< Working >>'!$R:$R, 'Supplier Wise Yearly'!C$6, '<< Working >>'!$L:$L, 'Supplier Wise Yearly'!$B9, '<< Working >>'!$N:$N, 'Supplier Wise Yearly'!$B$2) -> 6750 | D9: =SUMIFS('<< Working >>'!$J:$J, '<< Working >>'!$D:$D, 'Supplier Wise Yearly'!$B$1, '<< Working >>'!$R:$R, 'Supplier Wise Yearly'!D$6, '<< Working >>'!$L:$L, 'Supplier Wise Yearly'!$B9, '<< Working >>'!$N:$N, 'Supplier Wise Yearly'!$B$2) -> 72250 | E9: =SUMIFS('<< Working >>'!$J:$J, '<< Working >>'!$D:$D, 'Supplier Wise Yearly'!$B$1, '<< Working >>'!$R:$R, 'Supplier Wise Yearly'!E$6, '<< Working >>'!$L:$L, 'Supplier Wise Yearly'!$B9, '<< Working >>'!$N:$N, 'Supplier Wise Yearly'!$B$2) -> 53500 | F9: =SUMIFS('<< Working >>'!$J:$J, '<< Working >>'!$D:$D, 'Supplier Wise Yearly'!$B$1, '<< Working >>'!$R:$R, 'Supplier Wise Yearly'!F$6, '<< Working >>'!$L:$L, 'Supplier Wise Yearly'!$B9, '<< Working >>'!$N:$N, 'Supplier Wise Yearly'!$B$2) -> 58000 | G9: =SUMIFS('<< Working >>'!$J:$J, '<< Working >>'!$D:$D, 'Supplier Wise Yearly'!$B$1, '<< Working >>'!$R:$R, 'Supplier Wise Yearly'!G$6, '<< Working >>'!$L:$L, 'Supplier Wise Yearly'!$B9, '<< Working >>'!$N:$N, 'Supplier Wise Yearly'!$B$2) -> 55500 | H9: =SUMIFS('<< Working >>'!$J:$J, '<< Working >>'!$D:$D, 'Supplier Wise Yearly'!$B$1, '<< Working >>'!$R:$R, 'Supplier Wise Yearly'!H$6, '<< Working >>'!$L:$L, 'Supplier Wise Yearly'!$B9, '<< Working >>'!$N:$N, 'Supplier Wise Yearly'!$B$2) -> 49500 | I9: =SUMIFS('<< Working >>'!$J:$J, '<< Working >>'!$D:$D, 'Supplier Wise Yearly'!$B$1, '<< Working >>'!$R:$R, 'Supplier Wise Yearly'!I$6, '<< Working >>'!$L:$L, 'Supplier Wise Yearly'!$B9, '<< Working >>'!$N:$N, 'Supplier Wise Yearly'!$B$2) -> 79250 | J9: =SUMIFS('<< Working >>'!$J:$J, '<< Working >>'!$D:$D, 'Supplier Wise Yearly'!$B$1, '<< Working >>'!$R:$R, 'Supplier Wise Yearly'!J$6, '<< Working >>'!$L:$L, 'Supplier Wise Yearly'!$B9, '<< Working >>'!$N:$N, 'Supplier Wise Yearly'!$B$2) -> 40000 | ... N9: =SUMIFS('<< Working >>'!$J:$J, '<< Working >>'!$D:$D, 'Supplier Wise Yearly'!$B$1, '<< Working >>'!$R:$R, 'Supplier Wise Yearly'!N$6, '<< Working >>'!$L:$L, 'Supplier Wise Yearly'!$B9, '<< Working >>'!$N:$N, 'Supplier Wise Yearly'!$B$2) -> 0 | O9: =SUM(C9:N9) -> 414750 | Q9: =IF(O9>0, "Yes", "No") -> Yes
A10: =VLOOKUP(B10, 'Items Master'!E:F,2,0) -> Domestic | B10: GAIL | C10: =SUMIFS('<< Working >>'!$J:$J, '<< Working >>'!$D:$D, 'Supplier Wise Yearly'!$B$1, '<< Working >>'!$R:$R, 'Supplier Wise Yearly'!C$6, '<< Working >>'!$L:$L, 'Supplier Wise Yearly'!$B10, '<< Working >>'!$N:$N, 'Supplier Wise Yearly'!$B$2) -> 1000 | D10: =SUMIFS('<< Working >>'!$J:$J, '<< Working >>'!$D:$D, 'Supplier Wise Yearly'!$B$1, '<< Working >>'!$R:$R, 'Supplier Wise Yearly'!D$6, '<< Working >>'!$L:$L, 'Supplier Wise Yearly'!$B10, '<< Working >>'!$N:$N, 'Supplier Wise Yearly'!$B$2) -> 72500 | E10: =SUMIFS('<< Working >>'!$J:$J, '<< Working >>'!$D:$D, 'Supplier Wise Yearly'!$B$1, '<< Working >>'!$R:$R, 'Supplier Wise Yearly'!E$6, '<< Working >>'!$L:$L, 'Supplier Wise Yearly'!$B10, '<< Working >>'!$N:$N, 'Supplier Wise Yearly'!$B$2) -> 19000 | F10: =SUMIFS('<< Working >>'!$J:$J, '<< Working >>'!$D:$D, 'Supplier Wise Yearly'!$B$1, '<< Working >>'!$R:$R, 'Supplier Wise Yearly'!F$6, '<< Working >>'!$L:$L, 'Supplier Wise Yearly'!$B10, '<< Working >>'!$N:$N, 'Supplier Wise Yearly'!$B$2) -> 65750 | G10: =SUMIFS('<< Working >>'!$J:$J, '<< Working >>'!$D:$D, 'Supplier Wise Yearly'!$B$1, '<< Working >>'!$R:$R, 'Supplier Wise Yearly'!G$6, '<< Working >>'!$L:$L, 'Supplier Wise Yearly'!$B10, '<< Working >>'!$N:$N, 'Supplier Wise Yearly'!$B$2) -> 71500 | H10: =SUMIFS('<< Working >>'!$J:$J, '<< Working >>'!$D:$D, 'Supplier Wise Yearly'!$B$1, '<< Working >>'!$R:$R, 'Supplier Wise Yearly'!H$6, '<< Working >>'!$L:$L, 'Supplier Wise Yearly'!$B10, '<< Working >>'!$N:$N, 'Supplier Wise Yearly'!$B$2) -> 64750 | I10: =SUMIFS('<< Working >>'!$J:$J, '<< Working >>'!$D:$D, 'Supplier Wise Yearly'!$B$1, '<< Working >>'!$R:$R, 'Supplier Wise Yearly'!I$6, '<< Working >>'!$L:$L, 'Supplier Wise Yearly'!$B10, '<< Working >>'!$N:$N, 'Supplier Wise Yearly'!$B$2) -> 132500 | J10: =SUMIFS('<< Working >>'!$J:$J, '<< Working >>'!$D:$D, 'Supplier Wise Yearly'!$B$1, '<< Working >>'!$R:$R, 'Supplier Wise Yearly'!J$6, '<< Working >>'!$L:$L, 'Supplier Wise Yearly'!$B10, '<< Working >>'!$N:$N, 'Supplier Wise Yearly'!$B$2) -> 28500 | ... N10: =SUMIFS('<< Working >>'!$J:$J, '<< Working >>'!$D:$D, 'Supplier Wise Yearly'!$B$1, '<< Working >>'!$R:$R, 'Supplier Wise Yearly'!N$6, '<< Working >>'!$L:$L, 'Supplier Wise Yearly'!$B10, '<< Working >>'!$N:$N, 'Supplier Wise Yearly'!$B$2) -> 0 | O10: =SUM(C10:N10) -> 455500 | Q10: =IF(O10>0, "Yes", "No") -> Yes
A11: =VLOOKUP(B11, 'Items Master'!E:F,2,0) -> Domestic | B11: BCPL | C11: =SUMIFS('<< Working >>'!$J:$J, '<< Working >>'!$D:$D, 'Supplier Wise Yearly'!$B$1, '<< Working >>'!$R:$R, 'Supplier Wise Yearly'!C$6, '<< Working >>'!$L:$L, 'Supplier Wise Yearly'!$B11, '<< Working >>'!$N:$N, 'Supplier Wise Yearly'!$B$2) -> 0 | D11: =SUMIFS('<< Working >>'!$J:$J, '<< Working >>'!$D:$D, 'Supplier Wise Yearly'!$B$1, '<< Working >>'!$R:$R, 'Supplier Wise Yearly'!D$6, '<< Working >>'!$L:$L, 'Supplier Wise Yearly'!$B11, '<< Working >>'!$N:$N, 'Supplier Wise Yearly'!$B$2) -> 19000 | E11: =SUMIFS('<< Working >>'!$J:$J, '<< Working >>'!$D:$D, 'Supplier Wise Yearly'!$B$1, '<< Working >>'!$R:$R, 'Supplier Wise Yearly'!E$6, '<< Working >>'!$L:$L, 'Supplier Wise Yearly'!$B11, '<< Working >>'!$N:$N, 'Supplier Wise Yearly'!$B$2) -> 7000 | F11: =SUMIFS('<< Working >>'!$J:$J, '<< Working >>'!$D:$D, 'Supplier Wise Yearly'!$B$1, '<< Working >>'!$R:$R, 'Supplier Wise Yearly'!F$6, '<< Working >>'!$L:$L, 'Supplier Wise Yearly'!$B11, '<< Working >>'!$N:$N, 'Supplier Wise Yearly'!$B$2) -> 12500 | G11: =SUMIFS('<< Working >>'!$J:$J, '<< Working >>'!$D:$D, 'Supplier Wise Yearly'!$B$1, '<< Working >>'!$R:$R, 'Supplier Wise Yearly'!G$6, '<< Working >>'!$L:$L, 'Supplier Wise Yearly'!$B11, '<< Working >>'!$N:$N, 'Supplier Wise Yearly'!$B$2) -> 3000 | H11: =SUMIFS('<< Working >>'!$J:$J, '<< Working >>'!$D:$D, 'Supplier Wise Yearly'!$B$1, '<< Working >>'!$R:$R, 'Supplier Wise Yearly'!H$6, '<< Working >>'!$L:$L, 'Supplier Wise Yearly'!$B11, '<< Working >>'!$N:$N, 'Supplier Wise Yearly'!$B$2) -> 25750 | I11: =SUMIFS('<< Working >>'!$J:$J, '<< Working >>'!$D:$D, 'Supplier Wise Yearly'!$B$1, '<< Working >>'!$R:$R, 'Supplier Wise Yearly'!I$6, '<< Working >>'!$L:$L, 'Supplier Wise Yearly'!$B11, '<< Working >>'!$N:$N, 'Supplier Wise Yearly'!$B$2) -> 0 | J11: =SUMIFS('<< Working >>'!$J:$J, '<< Working >>'!$D:$D, 'Supplier Wise Yearly'!$B$1, '<< Working >>'!$R:$R, 'Supplier Wise Yearly'!J$6, '<< Working >>'!$L:$L, 'Supplier Wise Yearly'!$B11, '<< Working >>'!$N:$N, 'Supplier Wise Yearly'!$B$2) -> 1000 | ... N11: =SUMIFS('<< Working >>'!$J:$J, '<< Working >>'!$D:$D, 'Supplier Wise Yearly'!$B$1, '<< Working >>'!$R:$R, 'Supplier Wise Yearly'!N$6, '<< Working >>'!$L:$L, 'Supplier Wise Yearly'!$B11, '<< Working >>'!$N:$N, 'Supplier Wise Yearly'!$B$2) -> 0 | O11: =SUM(C11:N11) -> 68250 | Q11: =IF(O11>0, "Yes", "No") -> Yes
A12: =VLOOKUP(B12, 'Items Master'!E:F,2,0) -> Domestic | B12: OPAL | C12: =SUMIFS('<< Working >>'!$J:$J, '<< Working >>'!$D:$D, 'Supplier Wise Yearly'!$B$1, '<< Working >>'!$R:$R, 'Supplier Wise Yearly'!C$6, '<< Working >>'!$L:$L, 'Supplier Wise Yearly'!$B12, '<< Working >>'!$N:$N, 'Supplier Wise Yearly'!$B$2) -> 0 | D12: =SUMIFS('<< Working >>'!$J:$J, '<< Working >>'!$D:$D, 'Supplier Wise Yearly'!$B$1, '<< Working >>'!$R:$R, 'Supplier Wise Yearly'!D$6, '<< Working >>'!$L:$L, 'Supplier Wise Yearly'!$B12, '<< Working >>'!$N:$N, 'Supplier Wise Yearly'!$B$2) -> 0 | E12: =SUMIFS('<< Working >>'!$J:$J, '<< Working >>'!$D:$D, 'Supplier Wise Yearly'!$B$1, '<< Working >>'!$R:$R, 'Supplier Wise Yearly'!E$6, '<< Working >>'!$L:$L, 'Supplier Wise Yearly'!$B12, '<< Working >>'!$N:$N, 'Supplier Wise Yearly'!$B$2) -> 0 | F12: =SUMIFS('<< Working >>'!$J:$J, '<< Working >>'!$D:$D, 'Supplier Wise Yearly'!$B$1, '<< Working >>'!$R:$R, 'Supplier Wise Yearly'!F$6, '<< Working >>'!$L:$L, 'Supplier Wise Yearly'!$B12, '<< Working >>'!$N:$N, 'Supplier Wise Yearly'!$B$2) -> 0 | G12: =SUMIFS('<< Working >>'!$J:$J, '<< Working >>'!$D:$D, 'Supplier Wise Yearly'!$B$1, '<< Working >>'!$R:$R, 'Supplier Wise Yearly'!G$6, '<< Working >>'!$L:$L, 'Supplier Wise Yearly'!$B12, '<< Working >>'!$N:$N, 'Supplier Wise Yearly'!$B$2) -> 3000 | H12: =SUMIFS('<< Working >>'!$J:$J, '<< Working >>'!$D:$D, 'Supplier Wise Yearly'!$B$1, '<< Working >>'!$R:$R, 'Supplier Wise Yearly'!H$6, '<< Working >>'!$L:$L, 'Supplier Wise Yearly'!$B12, '<< Working >>'!$N:$N, 'Supplier Wise Yearly'!$B$2) -> 2500 | I12: =SUMIFS('<< Working >>'!$J:$J, '<< Working >>'!$D:$D, 'Supplier Wise Yearly'!$B$1, '<< Working >>'!$R:$R, 'Supplier Wise Yearly'!I$6, '<< Working >>'!$L:$L, 'Supplier Wise Yearly'!$B12, '<< Working >>'!$N:$N, 'Supplier Wise Yearly'!$B$2) -> 0 | J12: =SUMIFS('<< Working >>'!$J:$J, '<< Working >>'!$D:$D, 'Supplier Wise Yearly'!$B$1, '<< Working >>'!$R:$R, 'Supplier Wise Yearly'!J$6, '<< Working >>'!$L:$L, 'Supplier Wise Yearly'!$B12, '<< Working >>'!$N:$N, 'Supplier Wise Yearly'!$B$2) -> 0 | ... N12: =SUMIFS('<< Working >>'!$J:$J, '<< Working >>'!$D:$D, 'Supplier Wise Yearly'!$B$1, '<< Working >>'!$R:$R, 'Supplier Wise Yearly'!N$6, '<< Working >>'!$L:$L, 'Supplier Wise Yearly'!$B12, '<< Working >>'!$N:$N, 'Supplier Wise Yearly'!$B$2) -> 0 | O12: =SUM(C12:N12) -> 5500 | Q12: =IF(O12>0, "Yes", "No") -> Yes
A13: =VLOOKUP(B13, 'Items Master'!E:F,2,0) -> Domestic | B13: RIL | C13: =SUMIFS('<< Working >>'!$J:$J, '<< Working >>'!$D:$D, 'Supplier Wise Yearly'!$B$1, '<< Working >>'!$R:$R, 'Supplier Wise Yearly'!C$6, '<< Working >>'!$L:$L, 'Supplier Wise Yearly'!$B13, '<< Working >>'!$N:$N, 'Supplier Wise Yearly'!$B$2) -> 0 | D13: =SUMIFS('<< Working >>'!$J:$J, '<< Working >>'!$D:$D, 'Supplier Wise Yearly'!$B$1, '<< Working >>'!$R:$R, 'Supplier Wise Yearly'!D$6, '<< Working >>'!$L:$L, 'Supplier Wise Yearly'!$B13, '<< Working >>'!$N:$N, 'Supplier Wise Yearly'!$B$2) -> 0 | E13: =SUMIFS('<< Working >>'!$J:$J, '<< Working >>'!$D:$D, 'Supplier Wise Yearly'!$B$1, '<< Working >>'!$R:$R, 'Supplier Wise Yearly'!E$6, '<< Working >>'!$L:$L, 'Supplier Wise Yearly'!$B13, '<< Working >>'!$N:$N, 'Supplier Wise Yearly'!$B$2) -> 0 | F13: =SUMIFS('<< Working >>'!$J:$J, '<< Working >>'!$D:$D, 'Supplier Wise Yearly'!$B$1, '<< Working >>'!$R:$R, 'Supplier Wise Yearly'!F$6, '<< Working >>'!$L:$L, 'Supplier Wise Yearly'!$B13, '<< Working >>'!$N:$N, 'Supplier Wise Yearly'!$B$2) -> 0 | G13: =SUMIFS('<< Working >>'!$J:$J, '<< Working >>'!$D:$D, 'Supplier Wise Yearly'!$B$1, '<< Working >>'!$R:$R, 'Supplier Wise Yearly'!G$6, '<< Working >>'!$L:$L, 'Supplier Wise Yearly'!$B13, '<< Working >>'!$N:$N, 'Supplier Wise Yearly'!$B$2) -> 0 | H13: =SUMIFS('<< Working >>'!$J:$J, '<< Working >>'!$D:$D, 'Supplier Wise Yearly'!$B$1, '<< Working >>'!$R:$R, 'Supplier Wise Yearly'!H$6, '<< Working >>'!$L:$L, 'Supplier Wise Yearly'!$B13, '<< Working >>'!$N:$N, 'Supplier Wise Yearly'!$B$2) -> 0 | I13: =SUMIFS('<< Working >>'!$J:$J, '<< Working >>'!$D:$D, 'Supplier Wise Yearly'!$B$1, '<< Working >>'!$R:$R, 'Supplier Wise Yearly'!I$6, '<< Working >>'!$L:$L, 'Supplier Wise Yearly'!$B13, '<< Working >>'!$N:$N, 'Supplier Wise Yearly'!$B$2) -> 0 | J13: =SUMIFS('<< Working >>'!$J:$J, '<< Working >>'!$D:$D, 'Supplier Wise Yearly'!$B$1, '<< Working >>'!$R:$R, 'Supplier Wise Yearly'!J$6, '<< Working >>'!$L:$L, 'Supplier Wise Yearly'!$B13, '<< Working >>'!$N:$N, 'Supplier Wise Yearly'!$B$2) -> 0 | ... N13: =SUMIFS('<< Working >>'!$J:$J, '<< Working >>'!$D:$D, 'Supplier Wise Yearly'!$B$1, '<< Working >>'!$R:$R, 'Supplier Wise Yearly'!N$6, '<< Working >>'!$L:$L, 'Supplier Wise Yearly'!$B13, '<< Working >>'!$N:$N, 'Supplier Wise Yearly'!$B$2) -> 0 | O13: =SUM(C13:N13) -> 0 | Q13: =IF(O13>0, "Yes", "No") -> No
